<?xml version="1.0" ?>
<!-- =================================================================================== -->
<!-- |    This document was autogenerated by xacro from nandhi.urdf.xacro              | -->
<!-- |    EDITING THIS FILE BY HAND IS NOT RECOMMENDED                                 | -->
<!-- =================================================================================== -->
<robot name="nandhi">
  <material name="green">
    <color rgba="0 1 0 1"/>
  </material>
  <material name="blue">
    <color rgba="0 0 1 1"/>
  </material>
  <link name="base_footprint"/>
  <link name="base_link">
    <visual>
      <geometry>
        <box size="0.4 0.26 0.01"/>
      </geometry>
      <origin rpy="0 0 0" xyz="0 0 0.005"/>
      <material name="blue"/>
    </visual>
    <collision>
      <geometry>
        <box size="0.4 0.26 0.01"/>
      </geometry>
      <origin rpy="0 0 0" xyz="0 0 0.005"/>
    </collision>
    <inertial>
      <origin rpy="0 0 0" xyz="0 0 0.005"/>
      <mass value="3.0"/>
      <inertia ixx="0.040025000000000005" ixy="0" ixz="0" iyy="0.056900000000000006" iyz="0" izz="0.016925000000000003"/>
    </inertial>
  </link>
  <link name="front_left_wheel_link">
    <visual>
      <geometry>
        <cylinder length="0.04" radius="0.045"/>
      </geometry>
      <origin rpy="1.5707963267948966 0 0" xyz="0 0 0"/>
      <material name="green"/>
    </visual>
    <collision>
      <geometry>
        <cylinder length="0.04" radius="0.045"/>
      </geometry>
      <origin rpy="1.5707963267948966 0 0" xyz="0 0 0"/>
    </collision>
    <inertial>
      <origin rpy="1.5707963267948966 0 0" xyz="0 0 0"/>
      <mass value="0.1"/>
      <inertia ixx="6.395833333333333e-05" ixy="0" ixz="0" iyy="6.395833333333333e-05" iyz="0" izz="0.00010125"/>
    </inertial>
  </link>
  <link name="front_right_wheel_link">
    <visual>
      <geometry>
        <cylinder length="0.04" radius="0.045"/>
      </geometry>
      <origin rpy="1.5707963267948966 0 0" xyz="0 0 0"/>
      <material name="green"/>
    </visual>
    <collision>
      <geometry>
        <cylinder length="0.04" radius="0.045"/>
      </geometry>
      <origin rpy="1.5707963267948966 0 0" xyz="0 0 0"/>
    </collision>
    <inertial>
      <origin rpy="1.5707963267948966 0 0" xyz="0 0 0"/>
      <mass value="0.1"/>
      <inertia ixx="6.395833333333333e-05" ixy="0" ixz="0" iyy="6.395833333333333e-05" iyz="0" izz="0.00010125"/>
    </inertial>
  </link>
  <link name="rear_left_wheel_link">
    <visual>
      <geometry>
        <cylinder length="0.04" radius="0.045"/>
      </geometry>
      <origin rpy="1.5707963267948966 0 0" xyz="0 0 0"/>
      <material name="green"/>
    </visual>
    <collision>
      <geometry>
        <cylinder length="0.04" radius="0.045"/>
      </geometry>
      <origin rpy="1.5707963267948966 0 0" xyz="0 0 0"/>
    </collision>
    <inertial>
      <origin rpy="1.5707963267948966 0 0" xyz="0 0 0"/>
      <mass value="0.1"/>
      <inertia ixx="6.395833333333333e-05" ixy="0" ixz="0" iyy="6.395833333333333e-05" iyz="0" izz="0.00010125"/>
    </inertial>
  </link>
  <link name="rear_right_wheel_link">
    <visual>
      <geometry>
        <cylinder length="0.04" radius="0.045"/>
      </geometry>
      <origin rpy="1.5707963267948966 0 0" xyz="0 0 0"/>
      <material name="green"/>
    </visual>
    <collision>
      <geometry>
        <cylinder length="0.04" radius="0.045"/>
      </geometry>
      <origin rpy="1.5707963267948966 0 0" xyz="0 0 0"/>
    </collision>
    <inertial>
      <origin rpy="1.5707963267948966 0 0" xyz="0 0 0"/>
      <mass value="0.1"/>
      <inertia ixx="6.395833333333333e-05" ixy="0" ixz="0" iyy="6.395833333333333e-05" iyz="0" izz="0.00010125"/>
    </inertial>
  </link>
  <joint name="base_joint" type="fixed">
    <parent link="base_footprint"/>
    <child link="base_link"/>
    <origin rpy="0 0 0" xyz="0 0 0.045"/>
  </joint>
  <joint name="base_front_left_wheel_joint" type="continuous">
    <parent link="base_link"/>
    <child link="front_left_wheel_link"/>
    <origin rpy="0 0 0" xyz="-0.15 -0.15 0.005"/>
    <axis xyz="0 1 0"/>
  </joint>

  <joint name="base_front_right_wheel_joint" type="continuous">
    <parent link="base_link"/>
    <child link="front_right_wheel_link"/>
    <origin rpy="0 0 0" xyz="-0.15 0.15 0.005"/>
    <axis xyz="0 1 0"/>
  </joint>

  <joint name="base_rear_left_wheel_joint" type="continuous">
    <parent link="base_link"/>
    <child link="rear_left_wheel_link"/>
    <origin rpy="0 0 0" xyz="0.15 -0.15 0.005"/>
    <axis xyz="0 1 0"/>
  </joint>
  <joint name="base_rear_right_wheel_joint" type="continuous">
    <parent link="base_link"/>
    <child link="rear_right_wheel_link"/>
    <origin rpy="0 0 0" xyz="0.15 0.15 0.005"/>
    <axis xyz="0 1 0"/>
  </joint>
</robot>
