<?xml version="1.0"?>
<!--
  Gazebo Ackermann steering plugin demo

  Try sending commands:

    gz topic -t "/model/nandhi/cmd_vel" -m gz.msgs.Twist -p "linear: {x: 0.5}, angular: {z: 0.1}"

  Listen to odometry:

    gz topic -e -t /model/nandhi/odometry

-->
<sdf version="1.8">
  <model name='nandhi'>

    <link name='chassis'>
      <pose>-0.01 -0 0.025 0 0 0</pose>
      <inertial>
        <mass>3</mass>
        <inertia>
          <ixx>0.126164</ixx>
          <ixy>0</ixy>
          <ixz>0</ixz>
          <iyy>0.416519</iyy>
          <iyz>0</iyz>
          <izz>0.481014</izz>
        </inertia>
      </inertial>
      <visual name='visual'>
        <geometry>
          <box>
            <size>0.532 0.29 0.195</size>
          </box>
        </geometry>
        <material>
          <ambient>0.5 0.5 1.0 1</ambient>
          <diffuse>0.5 0.5 1.0 1</diffuse>
          <specular>0.0 0.0 1.0 1</specular>
        </material>
      </visual>
      <collision name='collision'>
        <geometry>
          <box>
            <size>0.532 0.29 0.195</size>
          </box>
        </geometry>
      </collision>
    </link>

    <link name='front_left_wheel'>
      <pose>0.266 0.185 -0.05 -1.5707 0 0</pose>
      <inertial>
        <mass>2</mass>
        <inertia>
          <ixx>0.145833</ixx>
          <ixy>0</ixy>
          <ixz>0</ixz>
          <iyy>0.145833</iyy>
          <iyz>0</iyz>
          <izz>0.125</izz>
        </inertia>
      </inertial>
      <visual name='visual'>
        <geometry>
          <cylinder>
            <length>0.04</length>
            <radius>0.05</radius>
          </cylinder>
        </geometry>
        <material>
          <ambient>0.2 0.2 0.2 1</ambient>
          <diffuse>0.2 0.2 0.2 1</diffuse>
          <specular>0.2 0.2 0.2 1</specular>
        </material>
      </visual>
      <collision name='collision'>
        <geometry>
          <cylinder>
            <length>0.04</length>
            <radius>0.05</radius>
          </cylinder>
        </geometry>
        <surface>
          <friction>
            <ode>
              <mu>0.5</mu>
              <mu2>1.0</mu2>
              <fdir1>0 0 1</fdir1>
            </ode>
            <bullet>
              <friction>0.5</friction>
              <friction2>1</friction2>
              <rolling_friction>0.1</rolling_friction>
            </bullet>
          </friction>
        </surface>
      </collision>
    </link>

    <link name='rear_left_wheel'>
      <pose>-0.266 0.185 -0.05 -1.5707 0 0</pose>
      <inertial>
        <mass>2</mass>
        <inertia>
          <ixx>0.145833</ixx>
          <ixy>0</ixy>
          <ixz>0</ixz>
          <iyy>0.145833</iyy>
          <iyz>0</iyz>
          <izz>0.125</izz>
        </inertia>
      </inertial>
      <visual name='visual'>
        <geometry>
          <cylinder>
            <length>0.04</length>
            <radius>0.05</radius>
          </cylinder>
        </geometry>
        <material>
          <ambient>0.2 0.2 0.2 1</ambient>
          <diffuse>0.2 0.2 0.2 1</diffuse>
          <specular>0.2 0.2 0.2 1</specular>
        </material>
      </visual>
      <collision name='collision'>
        <geometry>
          <cylinder>
            <length>0.04</length>
            <radius>0.05</radius>
          </cylinder>
        </geometry>
        <surface>
          <friction>
            <ode>
              <mu>0.5</mu>
              <mu2>1.0</mu2>
              <fdir1>0 0 1</fdir1>
            </ode>
            <bullet>
              <friction>0.5</friction>
              <friction2>1</friction2>
              <rolling_friction>0.5</rolling_friction>
            </bullet>
          </friction>
        </surface>
      </collision>
    </link>

    <link name='front_right_wheel'>
      <pose>0.266 -0.185 -0.05 -1.5707 0 0</pose>
      <inertial>
        <mass>2</mass>
        <inertia>
          <ixx>0.145833</ixx>
          <ixy>0</ixy>
          <ixz>0</ixz>
          <iyy>0.145833</iyy>
          <iyz>0</iyz>
          <izz>0.125</izz>
        </inertia>
      </inertial>
      <visual name='visual'>
        <geometry>
          <cylinder>
            <length>0.04</length>
            <radius>0.05</radius>
          </cylinder>
        </geometry>
        <material>
          <ambient>0.2 0.2 0.2 1</ambient>
          <diffuse>0.2 0.2 0.2 1</diffuse>
          <specular>0.2 0.2 0.2 1</specular>
        </material>
      </visual>
      <collision name='collision'>
        <geometry>
          <cylinder>
            <length>0.04</length>
            <radius>0.05</radius>
          </cylinder>
        </geometry>
        <surface>
          <friction>
            <ode>
              <mu>0.5</mu>
              <mu2>1.0</mu2>
              <fdir1>0 0 1</fdir1>
            </ode>
            <bullet>
              <friction>0.5</friction>
              <friction2>1</friction2>
              <rolling_friction>0.1</rolling_friction>
            </bullet>
          </friction>
        </surface>
      </collision>
    </link>

    <link name='rear_right_wheel'>
      <pose>-0.266 -0.185 -0.05 -1.5707 0 0</pose>
      <inertial>
        <mass>2</mass>
        <inertia>
          <ixx>0.145833</ixx>
          <ixy>0</ixy>
          <ixz>0</ixz>
          <iyy>0.145833</iyy>
          <iyz>0</iyz>
          <izz>0.125</izz>
        </inertia>
      </inertial>
      <visual name='visual'>
        <geometry>
          <cylinder>
            <length>0.04</length>
            <radius>0.05</radius>
          </cylinder>
        </geometry>
        <material>
          <ambient>0.2 0.2 0.2 1</ambient>
          <diffuse>0.2 0.2 0.2 1</diffuse>
          <specular>0.2 0.2 0.2 1</specular>
        </material>
      </visual>
      <collision name='collision'>
        <geometry>
          <cylinder>
            <length>0.04</length>
            <radius>0.05</radius>
          </cylinder>
        </geometry>
        <surface>
          <friction>
            <ode>
              <mu>0.5</mu>
              <mu2>1.0</mu2>
              <fdir1>0 0 1</fdir1>
            </ode>
            <bullet>
              <friction>0.5</friction>
              <friction2>1</friction2>
              <rolling_friction>0.5</rolling_friction>
            </bullet>
          </friction>
        </surface>
      </collision>
    </link>

    <link name="front_left_wheel_steering_link">
      <pose>0.25 0.145 -0.05 0 0 0</pose>
      <inertial>
        <mass>0.05</mass>
        <inertia>
          <ixx>0.0153</ixx>
          <iyy>0.025</iyy>
          <izz>0.0153</izz>
        </inertia>
      </inertial>
      <visual name="steering_link_visual">
        <pose>0 0 0 0 0 0</pose>
        <geometry>
          <cylinder>
            <length>0.02</length>
            <radius>0.02</radius>
          </cylinder>
        </geometry>
        <material>
          <ambient>1 1 1</ambient>
          <diffuse>1 1 1</diffuse>
        </material>
      </visual>
    </link>

    <link name="front_right_wheel_steering_link">
      <pose>0.25 -0.145 -0.05 0 0 0</pose>
      <inertial>
        <mass>0.05</mass>
        <inertia>
          <ixx>0.0153</ixx>
          <iyy>0.025</iyy>
          <izz>0.0153</izz>
        </inertia>
      </inertial>
      <visual name="steering_link_visual">
        <pose>0 0 0 0 0 0</pose>
        <geometry>
          <cylinder>
            <length>0.02</length>
            <radius>0.02</radius>
          </cylinder>
        </geometry>
        <material>
          <ambient>1 1 1</ambient>
          <diffuse>1 1 1</diffuse>
        </material>
      </visual>
    </link>

    <joint name="front_left_wheel_steering_joint" type="revolute">
      <child>front_left_wheel_steering_link</child>
      <parent>chassis</parent>
      <axis>
        <xyz>0 0 1</xyz>
        <limit>
          <lower>-0.6</lower>
          <upper>+0.6</upper>
          <velocity>1.0</velocity>
          <effort>25</effort>
        </limit>
      </axis>
    </joint>

    <joint name="front_right_wheel_steering_joint" type="revolute">
      <parent>chassis</parent>
      <child>front_right_wheel_steering_link</child>
      <axis>
        <xyz>0 0 1</xyz>
        <limit>
          <lower>-0.6</lower>
          <upper>+0.6</upper>
          <velocity>1.0</velocity>
          <effort>25</effort>
        </limit>
      </axis>
    </joint>

    <joint name='front_left_wheel_joint' type='revolute'>
      <parent>front_left_wheel_steering_link</parent>
      <child>front_left_wheel</child>
      <axis>
        <xyz>0 0 1</xyz>
        <limit>
          <lower>-1.79769e+308</lower>
          <upper>1.79769e+308</upper>
        </limit>
      </axis>
    </joint>

    <joint name='front_right_wheel_joint' type='revolute'>
      <parent>front_right_wheel_steering_link</parent>
      <child>front_right_wheel</child>
      <axis>
        <xyz>0 0 1</xyz>
        <limit>
          <lower>-1.79769e+308</lower>
          <upper>1.79769e+308</upper>
        </limit>
      </axis>
    </joint>

    <joint name='rear_left_wheel_joint' type='revolute'>
      <parent>chassis</parent>
      <child>rear_left_wheel</child>
      <axis>
        <xyz>0 0 1</xyz>
        <limit>
          <lower>-1.79769e+308</lower>
          <upper>1.79769e+308</upper>
        </limit>
      </axis>
    </joint>

    <joint name='rear_right_wheel_joint' type='revolute'>
      <parent>chassis</parent>
      <child>rear_right_wheel</child>
      <axis>
        <xyz>0 0 1</xyz>
        <limit>
          <lower>-1.79769e+308</lower>
          <upper>1.79769e+308</upper>
        </limit>
      </axis>
    </joint>

    <plugin
      filename="gz-sim-joint-state-publisher-system"
      name="gz::sim::systems::JointStatePublisher">
    </plugin>

    <plugin
      filename="gz-sim-pose-publisher-system"
      name="gz::sim::systems::PosePublisher">
      <publish_link_pose>true</publish_link_pose>
      <use_pose_vector_msg>true</use_pose_vector_msg>
      <static_publisher>true</static_publisher>
      <static_update_frequency>1</static_update_frequency>
    </plugin>

    <plugin
      filename="gz-sim-odometry-publisher-system"
      name="gz::sim::systems::OdometryPublisher">
      <odom_frame>nandhi/odom</odom_frame>
      <robot_base_frame>nandhi</robot_base_frame>
    </plugin>

    <plugin
      filename="gz-sim-ackermann-steering-system"
      name="gz::sim::systems::AckermannSteering">
      <left_joint>front_left_wheel_joint</left_joint>
      <left_joint>rear_left_wheel_joint</left_joint>
      <right_joint>front_right_wheel_joint</right_joint>
      <right_joint>rear_right_wheel_joint</right_joint>
      <left_steering_joint>front_left_wheel_steering_joint</left_steering_joint>
      <right_steering_joint>front_right_wheel_steering_joint</right_steering_joint>
      <kingpin_width>1.0</kingpin_width>
      <steering_limit>0.5235988</steering_limit>
      <wheel_base>0.29</wheel_base>
      <wheel_separation>0.532</wheel_separation>
      <wheel_radius>0.05</wheel_radius>
      <min_velocity>-13.89</min_velocity>
      <max_velocity>13.89</max_velocity>
      <min_acceleration>-3</min_acceleration>
      <max_acceleration>3</max_acceleration>
    </plugin>

    <!-- Below is sensor setup -->

    <link name="lidar_link">
      <pose>0 0 0.135 0 0 0</pose>
      <inertial>
        <mass>0.1</mass>
        <inertia>
          <ixx>0.000166667</ixx>
          <iyy>0.000166667</iyy>
          <izz>0.000166667</izz>
        </inertia>
      </inertial>
      <collision name="collision">
        <geometry>
          <box>
            <size>0.05 0.05 0.05</size>
          </box>
        </geometry>
      </collision>
      <visual name="visual">
        <geometry>
          <box>
            <size>0.05 0.05 0.05</size>
          </box>
        </geometry>
      </visual>
      <sensor name='gpu_lidar' type='gpu_lidar'>
        <pose>0 0 0.135 0 0 0</pose>
        <topic>/model/nandhi/lidar</topic>
        <gz_frame_id>nandhi/lidar_link</gz_frame_id>
        <update_rate>10</update_rate>
        <lidar>
          <scan>
            <horizontal>
              <samples>640</samples>
              <resolution>1</resolution>
              <min_angle>-1.396263</min_angle>
              <max_angle>1.396263</max_angle>
            </horizontal>
            <vertical>
              <samples>1</samples>
              <resolution>1</resolution>
              <min_angle>0.0</min_angle>
              <max_angle>0.0</max_angle>
            </vertical>
          </scan>
          <range>
            <min>0.08</min>
            <max>10.0</max>
            <resolution>0.01</resolution>
          </range>
        </lidar>
        <visualize>true</visualize>
      </sensor>
    </link>

    <joint name='lidar_joint' type='fixed'>
      <parent>chassis</parent>
      <child>lidar_link</child>
    </joint>


    <link name="camera_link">
      <pose>0.245 0 0.125 0 0 0</pose>
      <inertial>
        <mass>0.1</mass>
        <inertia>
          <ixx>0.000166667</ixx>
          <iyy>0.000166667</iyy>
          <izz>0.000166667</izz>
        </inertia>
      </inertial>
      <collision name="collision">
        <geometry>
          <box>
            <size>0.02 0.01 0.01</size>
          </box>
        </geometry>
      </collision>
      <visual name="visual">
        <geometry>
          <box>
            <size>0.02 0.01 0.01</size>
          </box>
        </geometry>
      </visual>
      <sensor name="camera" type="camera">
        <topic>/model/nandhi/camera</topic>
        <camera>
          <horizontal_fov>1.047</horizontal_fov>
          <image>
            <width>320</width>
            <height>240</height>
          </image>
          <clip>
            <near>0.1</near>
            <far>100</far>
          </clip>
        </camera>
        <always_on>1</always_on>
        <update_rate>30</update_rate>
        <visualize>true</visualize>
      </sensor>
    </link>

    <joint name='camera_joint' type='fixed'>
      <parent>chassis</parent>
      <child>camera_link</child>
    </joint>

  </model>

</sdf>