<?xml version="1.0"?>
<!--
  Gazebo Ackermann steering plugin demo

  Try sending commands:

    gz topic -t "/model/nandhi/cmd_vel" -m gz.msgs.Twist -p "linear: {x: 0.5}, angular: {z: 0.1}"

  Listen to odometry:

    gz topic -e -t /model/nandhi/odometry

-->
<sdf version="1.8">
  <model name='nandhi'>

    <link name='chassis'>
      <inertial>
        <pose>0 0 0 0 0 0</pose>
        <mass>3.0</mass>
        <inertia>
          <ixx>0.0054</ixx>
          <ixy>0</ixy>
          <ixz>0</ixz>
          <iyy>0.0252</iyy>
          <iyz>0</iyz>
          <izz>0.0252</izz>
        </inertia>
      </inertial>
      <visual name="base_visual">
        <pose>.1371 0 -.0115 -0.018 0 1.5707</pose>
        <geometry>
          <mesh>
            <uri>model://nandhi/meshes/BaseReduced.dae</uri>
          </mesh>
        </geometry>
      </visual>
      <visual name="top_visual">
        <pose>.1371 0 -.0115 -0.018 0 1.5707</pose>
        <geometry>
          <mesh>
            <uri>model://nandhi/meshes/TopReduced.dae</uri>
          </mesh>
        </geometry>
      </visual>
      <collision name="collision">
        <pose>0 0 .06 0 0 0</pose>
        <geometry>
          <box>
            <size>.3 .09 .12</size>
          </box>
        </geometry>
      </collision>
    </link>

    <link name='front_left_wheel'>
      <pose relative_to="front_left_wheel_joint">0 0 0 0 0 0</pose>
      <inertial>
        <mass>.05</mass>
        <inertia>
          <ixx>0.00003331</ixx>
          <ixy>0</ixy>
          <ixz>0</ixz>
          <iyy>0.0000204</iyy>
          <iyz>0</iyz>
          <izz>0.0000204</izz>
        </inertia>
      </inertial>
      <gravity>true</gravity>
      <velocity_decay />
      <visual name="front_left_wheel_visual">
        <pose>0 0 0 0 0 3.14159</pose>
        <geometry>
          <mesh>
            <uri>model://nandhi/meshes/Wheel.dae</uri>
          </mesh>
        </geometry>
      </visual>
      <collision name="front_left_wheel_collision">
        <pose>0 -.015 0 -1.5707 0 0</pose>
        <geometry>
          <cylinder>
            <length>0.03</length>
            <radius>0.0365</radius>
          </cylinder>
        </geometry>
        <surface>
          <friction>
            <ode>
              <mu>0.5</mu>
              <mu2>1.0</mu2>
              <fdir1>0 0 1</fdir1>
            </ode>
          </friction>
        </surface>
      </collision>
    </link>

    <link name='rear_left_wheel'>
      <pose relative_to="rear_left_wheel_joint">0 0 0 0 0 0</pose>
      <inertial>
        <mass>.05</mass>
        <inertia>
          <ixx>0.00003331</ixx>
          <ixy>0</ixy>
          <ixz>0</ixz>
          <iyy>0.0000204</iyy>
          <iyz>0</iyz>
          <izz>0.0000204</izz>
        </inertia>
      </inertial>
      <gravity>true</gravity>
      <velocity_decay />
      <visual name="rear_left_wheel_visual">
        <pose>0 0 0 0 0 3.14159</pose>
        <geometry>
          <mesh>
            <uri>model://nandhi/meshes/Wheel.dae</uri>
          </mesh>
        </geometry>
      </visual>
      <collision name="rear_left_wheel_collision">
        <pose>0 -.015 0 -1.5707 0 0</pose>
        <geometry>
          <cylinder>
            <length>0.03</length>
            <radius>0.0365</radius>
          </cylinder>
        </geometry>
        <surface>
          <friction>
            <ode>
              <mu>0.5</mu>
              <mu2>1.0</mu2>
              <fdir1>0 0 1</fdir1>
            </ode>
          </friction>
        </surface>
      </collision>
    </link>

    <link name='front_right_wheel'>
      <pose relative_to="front_right_wheel_joint">0 0 0 0 0 0</pose>
      <inertial>
        <mass>.05</mass>
        <inertia>
          <ixx>0.00003331</ixx>
          <ixy>0</ixy>
          <ixz>0</ixz>
          <iyy>0.0000204</iyy>
          <iyz>0</iyz>
          <izz>0.0000204</izz>
        </inertia>
      </inertial>
      <gravity>true</gravity>
      <velocity_decay />
      <visual name="front_right_wheel_visual">
        <pose>0 0 0 0 0 0</pose>
        <geometry>
          <mesh>
            <uri>model://nandhi/meshes/Wheel.dae</uri>
          </mesh>
        </geometry>
      </visual>
      <collision name="front_right_wheel_collision">
        <pose>0 .015 0 -1.5707 0 0</pose>
        <geometry>
          <cylinder>
            <length>0.03</length>
            <radius>0.0365</radius>
          </cylinder>
        </geometry>
        <surface>
          <friction>
            <ode>
              <mu>0.5</mu>
              <mu2>1.0</mu2>
              <fdir1>0 0 1</fdir1>
            </ode>
          </friction>
        </surface>
      </collision>
    </link>

    <link name='rear_right_wheel'>
      <pose relative_to="rear_right_wheel_joint">0 0 0 0 0 0</pose>
      <inertial>
        <mass>.05</mass>
        <inertia>
          <ixx>0.00003331</ixx>
          <ixy>0</ixy>
          <ixz>0</ixz>
          <iyy>0.0000204</iyy>
          <iyz>0</iyz>
          <izz>0.0000204</izz>
        </inertia>
      </inertial>
      <gravity>true</gravity>
      <velocity_decay />
      <visual name="rear_right_wheel_visual">
        <pose>0 0 0 0 0 0</pose>
        <geometry>
          <mesh>
            <uri>model://nandhi/meshes/Wheel.dae</uri>
          </mesh>
        </geometry>
      </visual>
      <collision name="rear_right_wheel_collision">
        <pose>0 .015 0 -1.5707 0 0</pose>
        <geometry>
          <cylinder>
            <length>0.03</length>
            <radius>0.0365</radius>
          </cylinder>
        </geometry>
        <surface>
          <friction>
            <ode>
              <mu>0.5</mu>
              <mu2>1.0</mu2>
              <fdir1>0 0 1</fdir1>
            </ode>
          </friction>
        </surface>
      </collision>
    </link>

    <link name="front_left_wheel_steering_link">
      <pose relative_to="front_left_wheel_steering_joint">0 0 0 0 0 0</pose>
      <inertial>
        <mass>0.005</mass>
        <inertia>
          <ixx>0.0000018</ixx>
          <iyy>0.0000018</iyy>
          <izz>0.0000018</izz>
        </inertia>
      </inertial>
    </link>

    <link name="front_right_wheel_steering_link">
      <pose relative_to="front_right_wheel_steering_joint">0 0 0 0 0 0</pose>
      <inertial>
        <mass>0.005</mass>
        <inertia>
          <ixx>0.0000018</ixx>
          <iyy>0.0000018</iyy>
          <izz>0.0000018</izz>
        </inertia>
      </inertial>
    </link>

    <joint name="front_left_wheel_steering_joint" type="revolute">
      <parent>chassis</parent>
      <child>front_left_wheel_steering_link</child>
      <pose relative_to="chassis">.112 .10 0 0 0 0</pose>
      <axis>
        <xyz>0 0 1</xyz>
        <limit>
          <lower>-0.6</lower>
          <upper>0.6</upper>
          <velocity>1.0</velocity>
          <effort>25</effort>
        </limit>
        <use_parent_model_frame>1</use_parent_model_frame>
      </axis>
    </joint>

    <joint name="front_right_wheel_steering_joint" type="revolute">
      <parent>chassis</parent>
      <child>front_right_wheel_steering_link</child>
      <pose relative_to="chassis">.112 -.10 0 0 0 0</pose>
      <axis>
        <xyz>0 0 1</xyz>
        <limit>
          <lower>-0.6</lower>
          <upper>0.6</upper>
          <velocity>1.0</velocity>
          <effort>25</effort>
        </limit>
        <use_parent_model_frame>1</use_parent_model_frame>
      </axis>
    </joint>

    <joint name='front_left_wheel_joint' type='revolute'>
      <parent>front_left_wheel_steering_link</parent>
      <child>front_left_wheel</child>
      <pose relative_to="front_left_wheel_steering_joint">0 0 0 0 0 0</pose>
      <axis>
        <xyz>0 1 0</xyz>
        <limit>
          <lower>-1.79769e+308</lower>
          <upper>1.79769e+308</upper>
        </limit>
        <dynamics>
          <spring_reference>0</spring_reference>
          <spring_stiffness>0</spring_stiffness>
        </dynamics>
        <use_parent_model_frame>1</use_parent_model_frame>
      </axis>
    </joint>

    <joint name='front_right_wheel_joint' type='revolute'>
      <parent>front_right_wheel_steering_link</parent>
      <child>front_right_wheel</child>
      <pose relative_to="front_right_wheel_steering_joint">0 0 0 0 0 0</pose>
      <axis>
        <xyz>0 1 0</xyz>
        <limit>
          <lower>-1.79769e+308</lower>
          <upper>1.79769e+308</upper>
        </limit>
        <dynamics>
          <spring_reference>0</spring_reference>
          <spring_stiffness>0</spring_stiffness>
        </dynamics>
        <use_parent_model_frame>1</use_parent_model_frame>
      </axis>
    </joint>

    <joint name='rear_left_wheel_joint' type='revolute'>
      <parent>chassis</parent>
      <child>rear_left_wheel</child>
      <pose relative_to="chassis">-.1135 .10 0 0 0 0</pose>
      <axis>
        <xyz>0 1 0</xyz>
        <limit>
          <lower>-1.79769e+308</lower>
          <upper>1.79769e+308</upper>
        </limit>
        <dynamics>
          <spring_reference>0</spring_reference>
          <spring_stiffness>0</spring_stiffness>
        </dynamics>
        <use_parent_model_frame>1</use_parent_model_frame>
      </axis>
    </joint>

    <joint name='rear_right_wheel_joint' type='revolute'>
      <parent>chassis</parent>
      <child>rear_right_wheel</child>
      <pose relative_to="chassis">-.1135 -.10 0 0 0 0</pose>
      <axis>
        <xyz>0 1 0</xyz>
        <limit>
          <lower>-1.79769e+308</lower>
          <upper>1.79769e+308</upper>
        </limit>
        <dynamics>
          <spring_reference>0</spring_reference>
          <spring_stiffness>0</spring_stiffness>
        </dynamics>
        <use_parent_model_frame>1</use_parent_model_frame>
      </axis>
    </joint>

    <!-- Below is sensor setup -->

    <link name="lidar_link">
      <pose>0 0 0.135 0 0 0</pose>
      <inertial>
        <mass>0.1</mass>
        <inertia>
          <ixx>0.000166667</ixx>
          <iyy>0.000166667</iyy>
          <izz>0.000166667</izz>
        </inertia>
      </inertial>
      <collision name="collision">
        <geometry>
          <box>
            <size>0.05 0.05 0.05</size>
          </box>
        </geometry>
      </collision>
      <visual name="visual">
        <geometry>
          <box>
            <size>0.05 0.05 0.05</size>
          </box>
        </geometry>
      </visual>
      <sensor name='gpu_lidar' type='gpu_lidar'>
        <pose>0 0 0.135 0 0 0</pose>
        <topic>/model/nandhi/lidar</topic>
        <gz_frame_id>nandhi/lidar_link</gz_frame_id>
        <update_rate>10</update_rate>
        <lidar>
          <scan>
            <horizontal>
              <samples>640</samples>
              <resolution>1</resolution>
              <min_angle>-1.396263</min_angle>
              <max_angle>1.396263</max_angle>
            </horizontal>
            <vertical>
              <samples>1</samples>
              <resolution>1</resolution>
              <min_angle>0.0</min_angle>
              <max_angle>0.0</max_angle>
            </vertical>
          </scan>
          <range>
            <min>0.08</min>
            <max>10.0</max>
            <resolution>0.01</resolution>
          </range>
        </lidar>
        <visualize>true</visualize>
      </sensor>
    </link>

    <joint name='lidar_joint' type='fixed'>
      <parent>chassis</parent>
      <child>lidar_link</child>
    </joint>

    <link name="camera_link">
      <pose>0.245 0 0.125 0 0 0</pose>
      <inertial>
        <mass>0.1</mass>
        <inertia>
          <ixx>0.000166667</ixx>
          <iyy>0.000166667</iyy>
          <izz>0.000166667</izz>
        </inertia>
      </inertial>
      <collision name="collision">
        <geometry>
          <box>
            <size>0.02 0.01 0.01</size>
          </box>
        </geometry>
      </collision>
      <visual name="visual">
        <geometry>
          <box>
            <size>0.02 0.01 0.01</size>
          </box>
        </geometry>
      </visual>
      <sensor name="camera" type="camera">
        <topic>/model/nandhi/camera</topic>
        <camera>
          <horizontal_fov>1.047</horizontal_fov>
          <image>
            <width>320</width>
            <height>240</height>
          </image>
          <clip>
            <near>0.1</near>
            <far>100</far>
          </clip>
        </camera>
        <always_on>1</always_on>
        <update_rate>30</update_rate>
        <visualize>true</visualize>
      </sensor>
    </link>

    <joint name='camera_joint' type='fixed'>
      <parent>chassis</parent>
      <child>camera_link</child>
    </joint>

    <plugin
      filename="gz-sim-joint-state-publisher-system"
      name="gz::sim::systems::JointStatePublisher">
    </plugin>

    <plugin
      filename="gz-sim-pose-publisher-system"
      name="gz::sim::systems::PosePublisher">
      <publish_link_pose>true</publish_link_pose>
      <use_pose_vector_msg>true</use_pose_vector_msg>
      <static_publisher>true</static_publisher>
      <static_update_frequency>1</static_update_frequency>
    </plugin>

    <plugin
      filename="gz-sim-ackermann-steering-system"
      name="gz::sim::systems::AckermannSteering">
      <left_joint>front_left_wheel_joint</left_joint>
      <left_joint>rear_left_wheel_joint</left_joint>
      <right_joint>front_right_wheel_joint</right_joint>
      <right_joint>rear_right_wheel_joint</right_joint>
      <left_steering_joint>front_left_wheel_steering_joint</left_steering_joint>
      <right_steering_joint>front_right_wheel_steering_joint</right_steering_joint>
      <kingpin_width>.18</kingpin_width>
      <steering_limit>0.5</steering_limit>
      <wheel_base>.2255</wheel_base>
      <wheel_separation>.2</wheel_separation>
      <wheel_radius>0.0365</wheel_radius>
      <min_velocity>-100</min_velocity>
      <max_velocity>100</max_velocity>
      <min_acceleration>-5</min_acceleration>
      <max_acceleration>5</max_acceleration>
    </plugin>
  </model>

</sdf>